<robot name="test_jorge">
  <link name="00">
	<visual>
         <geometry>
          <mesh filename="package://roboga_arm/meshes/00.stl" scale ="0.001 0.001 0.001"/>
         </geometry>
        </visual>
        <collision>
         <geometry>
          <mesh filename="package://roboga_arm/meshes/00.stl" scale ="0.001 0.001 0.001"/>
         </geometry>
        </collision>
  </link>

  <link name="01">
	<visual>
         <geometry>
          <mesh filename="package://roboga_arm/meshes/01.stl"/>
         </geometry>
        </visual>
        <collision>
         <geometry>
          <mesh filename="package://roboga_arm/meshes/01.stl"/>
         </geometry>
        </collision>
  </link>

  <link name="02">
	<visual>
         <geometry>
          <mesh filename="package://roboga_arm/meshes/02.stl"/>
         </geometry>
        </visual>
        <collision>
         <geometry>
          <mesh filename="package://roboga_arm/meshes/02.stl"/>
         </geometry>
        </collision>
  </link>

  <link name="03">
	<visual>
         <geometry>
          <mesh filename="package://roboga_arm/meshes/03.stl"/>
         </geometry>
        </visual>
        <collision>
         <geometry>
          <mesh filename="package://roboga_arm/meshes/03.stl"/>
         </geometry>
        </collision>
  </link>

  <link name="04">
	<visual>
         <geometry>
          <mesh filename="package://roboga_arm/meshes/04.stl"/>
         </geometry>
        </visual>
        <collision>
         <geometry>
          <mesh filename="package://roboga_arm/meshes/04.stl"/>
         </geometry>
        </collision>
  </link>

  <joint name="joint1" type="revolute">
    <axis xyz="0 0 1" />
    <limit effort="1000.0" lower="-1.708" upper="1.708" velocity="1.0" />
    <parent link="00"/>
    <child link="01"/>
  </joint>

  <joint name="joint2" type="revolute">
    <axis xyz="-1 0 0" />
    <limit effort="1000.0" lower="-1.708" upper="1.708" velocity="1.0" />
    <origin xyz="0 0 0.093" rpy="0 0 0" />
    <parent link="01"/>
    <child link="02"/>
  </joint>

  <joint name="joint3" type="revolute">
    <axis xyz="1 0 0" />
    <limit effort="1000.0" lower="-1.708" upper="1.708" velocity="1.0" />
    <origin xyz="0 0 0.121" rpy="0 0 0" />
    <parent link="02"/>
    <child link="03"/>
  </joint>

  <joint name="joint4" type="revolute">
    <axis xyz="-1 0 0" />
    <limit effort="1000.0" lower="-1.708" upper="1.708" velocity="1.0" />
    <origin xyz="0 0 0.112" rpy="0 0 0" />
    <parent link="03"/>
    <child link="04"/>
  </joint>

</robot>
